ERROR:    Exception in ASGI application
Traceback (most recent call last):
  File "/usr/local/lib/python3.10/dist-packages/gradio/routes.py", line 251, in main
    return templates.TemplateResponse(
  File "/root/cht/gpt_academic/themes/default.py", line 75, in gradio_new_template_fn
    res = gradio_original_template_fn(*args, **kwargs)
  File "/usr/local/lib/python3.10/dist-packages/starlette/templating.py", line 112, in TemplateResponse
    template = self.get_template(name)
  File "/usr/local/lib/python3.10/dist-packages/starlette/templating.py", line 94, in get_template
    return self.env.get_template(name)
  File "/usr/local/lib/python3.10/dist-packages/jinja2/environment.py", line 1010, in get_template
    return self._load_template(name, globals)
  File "/usr/local/lib/python3.10/dist-packages/jinja2/environment.py", line 969, in _load_template
    template = self.loader.load(self, name, self.make_globals(globals))
  File "/usr/local/lib/python3.10/dist-packages/jinja2/loaders.py", line 126, in load
    source, filename, uptodate = self.get_source(environment, name)
  File "/usr/local/lib/python3.10/dist-packages/jinja2/loaders.py", line 218, in get_source
    raise TemplateNotFound(template)
jinja2.exceptions.TemplateNotFound: frontend/share.html

The above exception was the direct cause of the following exception:

Traceback (most recent call last):
  File "/usr/local/lib/python3.10/dist-packages/uvicorn/protocols/http/h11_impl.py", line 408, in run_asgi
    result = await app(  # type: ignore[func-returns-value]
  File "/usr/local/lib/python3.10/dist-packages/uvicorn/middleware/proxy_headers.py", line 84, in __call__
    return await self.app(scope, receive, send)
  File "/usr/local/lib/python3.10/dist-packages/fastapi/applications.py", line 1106, in __call__
    await super().__call__(scope, receive, send)
  File "/usr/local/lib/python3.10/dist-packages/starlette/applications.py", line 122, in __call__
    await self.middleware_stack(scope, receive, send)
  File "/usr/local/lib/python3.10/dist-packages/starlette/middleware/errors.py", line 184, in __call__
    raise exc
  File "/usr/local/lib/python3.10/dist-packages/starlette/middleware/errors.py", line 162, in __call__
    await self.app(scope, receive, _send)
  File "/usr/local/lib/python3.10/dist-packages/starlette/middleware/cors.py", line 83, in __call__
    await self.app(scope, receive, send)
  File "/usr/local/lib/python3.10/dist-packages/starlette/middleware/exceptions.py", line 79, in __call__
    raise exc
  File "/usr/local/lib/python3.10/dist-packages/starlette/middleware/exceptions.py", line 68, in __call__
    await self.app(scope, receive, sender)
  File "/usr/local/lib/python3.10/dist-packages/fastapi/middleware/asyncexitstack.py", line 20, in __call__
    raise e
  File "/usr/local/lib/python3.10/dist-packages/fastapi/middleware/asyncexitstack.py", line 17, in __call__
    await self.app(scope, receive, send)
  File "/usr/local/lib/python3.10/dist-packages/starlette/routing.py", line 718, in __call__
    await route.handle(scope, receive, send)
  File "/usr/local/lib/python3.10/dist-packages/starlette/routing.py", line 276, in handle
    await self.app(scope, receive, send)
  File "/usr/local/lib/python3.10/dist-packages/starlette/routing.py", line 66, in app
    response = await func(request)
  File "/usr/local/lib/python3.10/dist-packages/fastapi/routing.py", line 274, in app
    raw_response = await run_endpoint_function(
  File "/usr/local/lib/python3.10/dist-packages/fastapi/routing.py", line 193, in run_endpoint_function
    return await run_in_threadpool(dependant.call, **values)
  File "/usr/local/lib/python3.10/dist-packages/starlette/concurrency.py", line 41, in run_in_threadpool
    return await anyio.to_thread.run_sync(func, *args)
  File "/usr/local/lib/python3.10/dist-packages/anyio/to_thread.py", line 33, in run_sync
    return await get_asynclib().run_sync_in_worker_thread(
  File "/usr/local/lib/python3.10/dist-packages/anyio/_backends/_asyncio.py", line 877, in run_sync_in_worker_thread
    return await future
  File "/usr/local/lib/python3.10/dist-packages/anyio/_backends/_asyncio.py", line 807, in run
    result = context.run(func, *args)
  File "/usr/local/lib/python3.10/dist-packages/gradio/routes.py", line 257, in main
    raise ValueError(
ValueError: Did you install Gradio from source files? Share mode only works when Gradio is installed through the pip package.
ERROR:    Exception in ASGI application
Traceback (most recent call last):
  File "/usr/local/lib/python3.10/dist-packages/gradio/routes.py", line 251, in main
    return templates.TemplateResponse(
  File "/root/cht/gpt_academic/themes/default.py", line 75, in gradio_new_template_fn
    res = gradio_original_template_fn(*args, **kwargs)
  File "/usr/local/lib/python3.10/dist-packages/starlette/templating.py", line 112, in TemplateResponse
    template = self.get_template(name)
  File "/usr/local/lib/python3.10/dist-packages/starlette/templating.py", line 94, in get_template
    return self.env.get_template(name)
  File "/usr/local/lib/python3.10/dist-packages/jinja2/environment.py", line 1010, in get_template
    return self._load_template(name, globals)
  File "/usr/local/lib/python3.10/dist-packages/jinja2/environment.py", line 969, in _load_template
    template = self.loader.load(self, name, self.make_globals(globals))
  File "/usr/local/lib/python3.10/dist-packages/jinja2/loaders.py", line 126, in load
    source, filename, uptodate = self.get_source(environment, name)
  File "/usr/local/lib/python3.10/dist-packages/jinja2/loaders.py", line 218, in get_source
    raise TemplateNotFound(template)
jinja2.exceptions.TemplateNotFound: frontend/share.html

The above exception was the direct cause of the following exception:

Traceback (most recent call last):
  File "/usr/local/lib/python3.10/dist-packages/uvicorn/protocols/http/h11_impl.py", line 408, in run_asgi
    result = await app(  # type: ignore[func-returns-value]
  File "/usr/local/lib/python3.10/dist-packages/uvicorn/middleware/proxy_headers.py", line 84, in __call__
    return await self.app(scope, receive, send)
  File "/usr/local/lib/python3.10/dist-packages/fastapi/applications.py", line 1106, in __call__
    await super().__call__(scope, receive, send)
  File "/usr/local/lib/python3.10/dist-packages/starlette/applications.py", line 122, in __call__
    await self.middleware_stack(scope, receive, send)
  File "/usr/local/lib/python3.10/dist-packages/starlette/middleware/errors.py", line 184, in __call__
    raise exc
  File "/usr/local/lib/python3.10/dist-packages/starlette/middleware/errors.py", line 162, in __call__
    await self.app(scope, receive, _send)
  File "/usr/local/lib/python3.10/dist-packages/starlette/middleware/cors.py", line 83, in __call__
    await self.app(scope, receive, send)
  File "/usr/local/lib/python3.10/dist-packages/starlette/middleware/exceptions.py", line 79, in __call__
    raise exc
  File "/usr/local/lib/python3.10/dist-packages/starlette/middleware/exceptions.py", line 68, in __call__
    await self.app(scope, receive, sender)
  File "/usr/local/lib/python3.10/dist-packages/fastapi/middleware/asyncexitstack.py", line 20, in __call__
    raise e
  File "/usr/local/lib/python3.10/dist-packages/fastapi/middleware/asyncexitstack.py", line 17, in __call__
    await self.app(scope, receive, send)
  File "/usr/local/lib/python3.10/dist-packages/starlette/routing.py", line 718, in __call__
    await route.handle(scope, receive, send)
  File "/usr/local/lib/python3.10/dist-packages/starlette/routing.py", line 276, in handle
    await self.app(scope, receive, send)
  File "/usr/local/lib/python3.10/dist-packages/starlette/routing.py", line 66, in app
    response = await func(request)
  File "/usr/local/lib/python3.10/dist-packages/fastapi/routing.py", line 274, in app
    raw_response = await run_endpoint_function(
  File "/usr/local/lib/python3.10/dist-packages/fastapi/routing.py", line 193, in run_endpoint_function
    return await run_in_threadpool(dependant.call, **values)
  File "/usr/local/lib/python3.10/dist-packages/starlette/concurrency.py", line 41, in run_in_threadpool
    return await anyio.to_thread.run_sync(func, *args)
  File "/usr/local/lib/python3.10/dist-packages/anyio/to_thread.py", line 33, in run_sync
    return await get_asynclib().run_sync_in_worker_thread(
  File "/usr/local/lib/python3.10/dist-packages/anyio/_backends/_asyncio.py", line 877, in run_sync_in_worker_thread
    return await future
  File "/usr/local/lib/python3.10/dist-packages/anyio/_backends/_asyncio.py", line 807, in run
    result = context.run(func, *args)
  File "/usr/local/lib/python3.10/dist-packages/gradio/routes.py", line 257, in main
    raise ValueError(
ValueError: Did you install Gradio from source files? Share mode only works when Gradio is installed through the pip package.
ERROR:    Exception in ASGI application
Traceback (most recent call last):
  File "/usr/local/lib/python3.10/dist-packages/gradio/routes.py", line 251, in main
    return templates.TemplateResponse(
  File "/root/cht/gpt_academic/themes/default.py", line 75, in gradio_new_template_fn
    res = gradio_original_template_fn(*args, **kwargs)
  File "/usr/local/lib/python3.10/dist-packages/starlette/templating.py", line 112, in TemplateResponse
    template = self.get_template(name)
  File "/usr/local/lib/python3.10/dist-packages/starlette/templating.py", line 94, in get_template
    return self.env.get_template(name)
  File "/usr/local/lib/python3.10/dist-packages/jinja2/environment.py", line 1010, in get_template
    return self._load_template(name, globals)
  File "/usr/local/lib/python3.10/dist-packages/jinja2/environment.py", line 969, in _load_template
    template = self.loader.load(self, name, self.make_globals(globals))
  File "/usr/local/lib/python3.10/dist-packages/jinja2/loaders.py", line 126, in load
    source, filename, uptodate = self.get_source(environment, name)
  File "/usr/local/lib/python3.10/dist-packages/jinja2/loaders.py", line 218, in get_source
    raise TemplateNotFound(template)
jinja2.exceptions.TemplateNotFound: frontend/share.html

The above exception was the direct cause of the following exception:

Traceback (most recent call last):
  File "/usr/local/lib/python3.10/dist-packages/uvicorn/protocols/http/h11_impl.py", line 408, in run_asgi
    result = await app(  # type: ignore[func-returns-value]
  File "/usr/local/lib/python3.10/dist-packages/uvicorn/middleware/proxy_headers.py", line 84, in __call__
    return await self.app(scope, receive, send)
  File "/usr/local/lib/python3.10/dist-packages/fastapi/applications.py", line 1106, in __call__
    await super().__call__(scope, receive, send)
  File "/usr/local/lib/python3.10/dist-packages/starlette/applications.py", line 122, in __call__
    await self.middleware_stack(scope, receive, send)
  File "/usr/local/lib/python3.10/dist-packages/starlette/middleware/errors.py", line 184, in __call__
    raise exc
  File "/usr/local/lib/python3.10/dist-packages/starlette/middleware/errors.py", line 162, in __call__
    await self.app(scope, receive, _send)
  File "/usr/local/lib/python3.10/dist-packages/starlette/middleware/cors.py", line 83, in __call__
    await self.app(scope, receive, send)
  File "/usr/local/lib/python3.10/dist-packages/starlette/middleware/exceptions.py", line 79, in __call__
    raise exc
  File "/usr/local/lib/python3.10/dist-packages/starlette/middleware/exceptions.py", line 68, in __call__
    await self.app(scope, receive, sender)
  File "/usr/local/lib/python3.10/dist-packages/fastapi/middleware/asyncexitstack.py", line 20, in __call__
    raise e
  File "/usr/local/lib/python3.10/dist-packages/fastapi/middleware/asyncexitstack.py", line 17, in __call__
    await self.app(scope, receive, send)
  File "/usr/local/lib/python3.10/dist-packages/starlette/routing.py", line 718, in __call__
    await route.handle(scope, receive, send)
  File "/usr/local/lib/python3.10/dist-packages/starlette/routing.py", line 276, in handle
    await self.app(scope, receive, send)
  File "/usr/local/lib/python3.10/dist-packages/starlette/routing.py", line 66, in app
    response = await func(request)
  File "/usr/local/lib/python3.10/dist-packages/fastapi/routing.py", line 274, in app
    raw_response = await run_endpoint_function(
  File "/usr/local/lib/python3.10/dist-packages/fastapi/routing.py", line 193, in run_endpoint_function
    return await run_in_threadpool(dependant.call, **values)
  File "/usr/local/lib/python3.10/dist-packages/starlette/concurrency.py", line 41, in run_in_threadpool
    return await anyio.to_thread.run_sync(func, *args)
  File "/usr/local/lib/python3.10/dist-packages/anyio/to_thread.py", line 33, in run_sync
    return await get_asynclib().run_sync_in_worker_thread(
  File "/usr/local/lib/python3.10/dist-packages/anyio/_backends/_asyncio.py", line 877, in run_sync_in_worker_thread
    return await future
  File "/usr/local/lib/python3.10/dist-packages/anyio/_backends/_asyncio.py", line 807, in run
    result = context.run(func, *args)
  File "/usr/local/lib/python3.10/dist-packages/gradio/routes.py", line 257, in main
    raise ValueError(
ValueError: Did you install Gradio from source files? Share mode only works when Gradio is installed through the pip package.
ERROR:    Exception in ASGI application
Traceback (most recent call last):
  File "/usr/local/lib/python3.10/dist-packages/gradio/routes.py", line 251, in main
    return templates.TemplateResponse(
  File "/root/cht/gpt_academic/themes/default.py", line 75, in gradio_new_template_fn
    res = gradio_original_template_fn(*args, **kwargs)
  File "/usr/local/lib/python3.10/dist-packages/starlette/templating.py", line 112, in TemplateResponse
    template = self.get_template(name)
  File "/usr/local/lib/python3.10/dist-packages/starlette/templating.py", line 94, in get_template
    return self.env.get_template(name)
  File "/usr/local/lib/python3.10/dist-packages/jinja2/environment.py", line 1010, in get_template
    return self._load_template(name, globals)
  File "/usr/local/lib/python3.10/dist-packages/jinja2/environment.py", line 969, in _load_template
    template = self.loader.load(self, name, self.make_globals(globals))
  File "/usr/local/lib/python3.10/dist-packages/jinja2/loaders.py", line 126, in load
    source, filename, uptodate = self.get_source(environment, name)
  File "/usr/local/lib/python3.10/dist-packages/jinja2/loaders.py", line 218, in get_source
    raise TemplateNotFound(template)
jinja2.exceptions.TemplateNotFound: frontend/share.html

The above exception was the direct cause of the following exception:

Traceback (most recent call last):
  File "/usr/local/lib/python3.10/dist-packages/uvicorn/protocols/http/h11_impl.py", line 408, in run_asgi
    result = await app(  # type: ignore[func-returns-value]
  File "/usr/local/lib/python3.10/dist-packages/uvicorn/middleware/proxy_headers.py", line 84, in __call__
    return await self.app(scope, receive, send)
  File "/usr/local/lib/python3.10/dist-packages/fastapi/applications.py", line 1106, in __call__
    await super().__call__(scope, receive, send)
  File "/usr/local/lib/python3.10/dist-packages/starlette/applications.py", line 122, in __call__
    await self.middleware_stack(scope, receive, send)
  File "/usr/local/lib/python3.10/dist-packages/starlette/middleware/errors.py", line 184, in __call__
    raise exc
  File "/usr/local/lib/python3.10/dist-packages/starlette/middleware/errors.py", line 162, in __call__
    await self.app(scope, receive, _send)
  File "/usr/local/lib/python3.10/dist-packages/starlette/middleware/cors.py", line 83, in __call__
    await self.app(scope, receive, send)
  File "/usr/local/lib/python3.10/dist-packages/starlette/middleware/exceptions.py", line 79, in __call__
    raise exc
  File "/usr/local/lib/python3.10/dist-packages/starlette/middleware/exceptions.py", line 68, in __call__
    await self.app(scope, receive, sender)
  File "/usr/local/lib/python3.10/dist-packages/fastapi/middleware/asyncexitstack.py", line 20, in __call__
    raise e
  File "/usr/local/lib/python3.10/dist-packages/fastapi/middleware/asyncexitstack.py", line 17, in __call__
    await self.app(scope, receive, send)
  File "/usr/local/lib/python3.10/dist-packages/starlette/routing.py", line 718, in __call__
    await route.handle(scope, receive, send)
  File "/usr/local/lib/python3.10/dist-packages/starlette/routing.py", line 276, in handle
    await self.app(scope, receive, send)
  File "/usr/local/lib/python3.10/dist-packages/starlette/routing.py", line 66, in app
    response = await func(request)
  File "/usr/local/lib/python3.10/dist-packages/fastapi/routing.py", line 274, in app
    raw_response = await run_endpoint_function(
  File "/usr/local/lib/python3.10/dist-packages/fastapi/routing.py", line 193, in run_endpoint_function
    return await run_in_threadpool(dependant.call, **values)
  File "/usr/local/lib/python3.10/dist-packages/starlette/concurrency.py", line 41, in run_in_threadpool
    return await anyio.to_thread.run_sync(func, *args)
  File "/usr/local/lib/python3.10/dist-packages/anyio/to_thread.py", line 33, in run_sync
    return await get_asynclib().run_sync_in_worker_thread(
  File "/usr/local/lib/python3.10/dist-packages/anyio/_backends/_asyncio.py", line 877, in run_sync_in_worker_thread
    return await future
  File "/usr/local/lib/python3.10/dist-packages/anyio/_backends/_asyncio.py", line 807, in run
    result = context.run(func, *args)
  File "/usr/local/lib/python3.10/dist-packages/gradio/routes.py", line 257, in main
    raise ValueError(
ValueError: Did you install Gradio from source files? Share mode only works when Gradio is installed through the pip package.
ERROR:    Exception in ASGI application
Traceback (most recent call last):
  File "/usr/local/lib/python3.10/dist-packages/gradio/routes.py", line 251, in main
    return templates.TemplateResponse(
  File "/root/cht/gpt_academic/themes/default.py", line 75, in gradio_new_template_fn
    res = gradio_original_template_fn(*args, **kwargs)
  File "/usr/local/lib/python3.10/dist-packages/starlette/templating.py", line 112, in TemplateResponse
    template = self.get_template(name)
  File "/usr/local/lib/python3.10/dist-packages/starlette/templating.py", line 94, in get_template
    return self.env.get_template(name)
  File "/usr/local/lib/python3.10/dist-packages/jinja2/environment.py", line 1010, in get_template
    return self._load_template(name, globals)
  File "/usr/local/lib/python3.10/dist-packages/jinja2/environment.py", line 969, in _load_template
    template = self.loader.load(self, name, self.make_globals(globals))
  File "/usr/local/lib/python3.10/dist-packages/jinja2/loaders.py", line 126, in load
    source, filename, uptodate = self.get_source(environment, name)
  File "/usr/local/lib/python3.10/dist-packages/jinja2/loaders.py", line 218, in get_source
    raise TemplateNotFound(template)
jinja2.exceptions.TemplateNotFound: frontend/share.html

The above exception was the direct cause of the following exception:

Traceback (most recent call last):
  File "/usr/local/lib/python3.10/dist-packages/uvicorn/protocols/http/h11_impl.py", line 408, in run_asgi
    result = await app(  # type: ignore[func-returns-value]
  File "/usr/local/lib/python3.10/dist-packages/uvicorn/middleware/proxy_headers.py", line 84, in __call__
    return await self.app(scope, receive, send)
  File "/usr/local/lib/python3.10/dist-packages/fastapi/applications.py", line 1106, in __call__
    await super().__call__(scope, receive, send)
  File "/usr/local/lib/python3.10/dist-packages/starlette/applications.py", line 122, in __call__
    await self.middleware_stack(scope, receive, send)
  File "/usr/local/lib/python3.10/dist-packages/starlette/middleware/errors.py", line 184, in __call__
    raise exc
  File "/usr/local/lib/python3.10/dist-packages/starlette/middleware/errors.py", line 162, in __call__
    await self.app(scope, receive, _send)
  File "/usr/local/lib/python3.10/dist-packages/starlette/middleware/cors.py", line 83, in __call__
    await self.app(scope, receive, send)
  File "/usr/local/lib/python3.10/dist-packages/starlette/middleware/exceptions.py", line 79, in __call__
    raise exc
  File "/usr/local/lib/python3.10/dist-packages/starlette/middleware/exceptions.py", line 68, in __call__
    await self.app(scope, receive, sender)
  File "/usr/local/lib/python3.10/dist-packages/fastapi/middleware/asyncexitstack.py", line 20, in __call__
    raise e
  File "/usr/local/lib/python3.10/dist-packages/fastapi/middleware/asyncexitstack.py", line 17, in __call__
    await self.app(scope, receive, send)
  File "/usr/local/lib/python3.10/dist-packages/starlette/routing.py", line 718, in __call__
    await route.handle(scope, receive, send)
  File "/usr/local/lib/python3.10/dist-packages/starlette/routing.py", line 276, in handle
    await self.app(scope, receive, send)
  File "/usr/local/lib/python3.10/dist-packages/starlette/routing.py", line 66, in app
    response = await func(request)
  File "/usr/local/lib/python3.10/dist-packages/fastapi/routing.py", line 274, in app
    raw_response = await run_endpoint_function(
  File "/usr/local/lib/python3.10/dist-packages/fastapi/routing.py", line 193, in run_endpoint_function
    return await run_in_threadpool(dependant.call, **values)
  File "/usr/local/lib/python3.10/dist-packages/starlette/concurrency.py", line 41, in run_in_threadpool
    return await anyio.to_thread.run_sync(func, *args)
  File "/usr/local/lib/python3.10/dist-packages/anyio/to_thread.py", line 33, in run_sync
    return await get_asynclib().run_sync_in_worker_thread(
  File "/usr/local/lib/python3.10/dist-packages/anyio/_backends/_asyncio.py", line 877, in run_sync_in_worker_thread
    return await future
  File "/usr/local/lib/python3.10/dist-packages/anyio/_backends/_asyncio.py", line 807, in run
    result = context.run(func, *args)
  File "/usr/local/lib/python3.10/dist-packages/gradio/routes.py", line 257, in main
    raise ValueError(
ValueError: Did you install Gradio from source files? Share mode only works when Gradio is installed through the pip package.
[1;31m [PROXY] 网络代理状态：未配置。无代理状态下很可能无法访问OpenAI家族的模型。建议：检查USE_PROXY选项是否修改。 [0m
所有问询记录将自动保存在本地目录./gpt_log/chat_secrets.log, 请注意自我隐私保护哦！
代理配置 无, 代理所在地：China
[1;34m [API_KEY] 本项目现已支持OpenAI和Azure的api-key。也支持同时填写多个api-key，如API_KEY="openai-key1,openai-key2,azure-key3" [0m
[1;34m [API_KEY] 您既可以在config.py中修改api-key(s)，也可以在问题输入区输入临时的api-key(s)，然后回车键提交后即可生效。 [0m
[1;32m [API_KEY] 您的 API_KEY 是: sk-rwefH6RwYUnw*** API_KEY 导入成功 [0m
如果浏览器没有自动打开，请复制并转到以下URL：
	「暗色主题已启用（支持动态切换主题）」: http://localhost:36925
Running on local URL:  http://0.0.0.0:36925
正在执行一些模块的预热 ...
正在加载tokenizer，如果是第一次运行，可能需要一点时间下载参数
加载tokenizer完毕
正在加载tokenizer，如果是第一次运行，可能需要一点时间下载参数
加载tokenizer完毕
Traceback (most recent call last):
  File "/root/cht/gpt_academic/main.py", line 454, in <module>
    main()
  File "/root/cht/gpt_academic/main.py", line 428, in main
    demo.queue(concurrency_count=CONCURRENT_COUNT).launch(
  File "/usr/local/lib/python3.10/dist-packages/gradio/blocks.py", line 1834, in launch
    self.share_url = networking.setup_tunnel(
  File "/usr/local/lib/python3.10/dist-packages/gradio/networking.py", line 177, in setup_tunnel
    address = tunnel.start_tunnel()
  File "/usr/local/lib/python3.10/dist-packages/gradio/tunneling.py", line 60, in start_tunnel
    binary_path = self.download_binary()
  File "/usr/local/lib/python3.10/dist-packages/gradio/tunneling.py", line 41, in download_binary
    resp = requests.get(binary_url)
  File "/usr/local/lib/python3.10/dist-packages/requests/api.py", line 73, in get
    return request("get", url, params=params, **kwargs)
  File "/usr/local/lib/python3.10/dist-packages/requests/api.py", line 59, in request
    return session.request(method=method, url=url, **kwargs)
  File "/usr/local/lib/python3.10/dist-packages/requests/sessions.py", line 587, in request
    resp = self.send(prep, **send_kwargs)
  File "/usr/local/lib/python3.10/dist-packages/requests/sessions.py", line 701, in send
    r = adapter.send(request, **kwargs)
  File "/usr/local/lib/python3.10/dist-packages/requests/adapters.py", line 486, in send
    resp = conn.urlopen(
  File "/usr/local/lib/python3.10/dist-packages/urllib3/connectionpool.py", line 790, in urlopen
    response = self._make_request(
  File "/usr/local/lib/python3.10/dist-packages/urllib3/connectionpool.py", line 467, in _make_request
    self._validate_conn(conn)
  File "/usr/local/lib/python3.10/dist-packages/urllib3/connectionpool.py", line 1092, in _validate_conn
    conn.connect()
  File "/usr/local/lib/python3.10/dist-packages/urllib3/connection.py", line 604, in connect
    self.sock = sock = self._new_conn()
  File "/usr/local/lib/python3.10/dist-packages/urllib3/connection.py", line 200, in _new_conn
    sock = connection.create_connection(
  File "/usr/local/lib/python3.10/dist-packages/urllib3/util/connection.py", line 73, in create_connection
    sock.connect(sa)
KeyboardInterrupt
ERROR:    Exception in ASGI application
Traceback (most recent call last):
  File "/usr/local/lib/python3.10/dist-packages/gradio/routes.py", line 251, in main
    return templates.TemplateResponse(
  File "/root/cht/gpt_academic/themes/default.py", line 75, in gradio_new_template_fn
    res = gradio_original_template_fn(*args, **kwargs)
  File "/usr/local/lib/python3.10/dist-packages/starlette/templating.py", line 112, in TemplateResponse
    template = self.get_template(name)
  File "/usr/local/lib/python3.10/dist-packages/starlette/templating.py", line 94, in get_template
    return self.env.get_template(name)
  File "/usr/local/lib/python3.10/dist-packages/jinja2/environment.py", line 1010, in get_template
    return self._load_template(name, globals)
  File "/usr/local/lib/python3.10/dist-packages/jinja2/environment.py", line 969, in _load_template
    template = self.loader.load(self, name, self.make_globals(globals))
  File "/usr/local/lib/python3.10/dist-packages/jinja2/loaders.py", line 126, in load
    source, filename, uptodate = self.get_source(environment, name)
  File "/usr/local/lib/python3.10/dist-packages/jinja2/loaders.py", line 218, in get_source
    raise TemplateNotFound(template)
jinja2.exceptions.TemplateNotFound: frontend/share.html

The above exception was the direct cause of the following exception:

Traceback (most recent call last):
  File "/usr/local/lib/python3.10/dist-packages/uvicorn/protocols/http/h11_impl.py", line 408, in run_asgi
    result = await app(  # type: ignore[func-returns-value]
  File "/usr/local/lib/python3.10/dist-packages/uvicorn/middleware/proxy_headers.py", line 84, in __call__
    return await self.app(scope, receive, send)
  File "/usr/local/lib/python3.10/dist-packages/fastapi/applications.py", line 1106, in __call__
    await super().__call__(scope, receive, send)
  File "/usr/local/lib/python3.10/dist-packages/starlette/applications.py", line 122, in __call__
    await self.middleware_stack(scope, receive, send)
  File "/usr/local/lib/python3.10/dist-packages/starlette/middleware/errors.py", line 184, in __call__
    raise exc
  File "/usr/local/lib/python3.10/dist-packages/starlette/middleware/errors.py", line 162, in __call__
    await self.app(scope, receive, _send)
  File "/usr/local/lib/python3.10/dist-packages/starlette/middleware/cors.py", line 83, in __call__
    await self.app(scope, receive, send)
  File "/usr/local/lib/python3.10/dist-packages/starlette/middleware/exceptions.py", line 79, in __call__
    raise exc
  File "/usr/local/lib/python3.10/dist-packages/starlette/middleware/exceptions.py", line 68, in __call__
    await self.app(scope, receive, sender)
  File "/usr/local/lib/python3.10/dist-packages/fastapi/middleware/asyncexitstack.py", line 20, in __call__
    raise e
  File "/usr/local/lib/python3.10/dist-packages/fastapi/middleware/asyncexitstack.py", line 17, in __call__
    await self.app(scope, receive, send)
  File "/usr/local/lib/python3.10/dist-packages/starlette/routing.py", line 718, in __call__
    await route.handle(scope, receive, send)
  File "/usr/local/lib/python3.10/dist-packages/starlette/routing.py", line 276, in handle
    await self.app(scope, receive, send)
  File "/usr/local/lib/python3.10/dist-packages/starlette/routing.py", line 66, in app
    response = await func(request)
  File "/usr/local/lib/python3.10/dist-packages/fastapi/routing.py", line 274, in app
    raw_response = await run_endpoint_function(
  File "/usr/local/lib/python3.10/dist-packages/fastapi/routing.py", line 193, in run_endpoint_function
    return await run_in_threadpool(dependant.call, **values)
  File "/usr/local/lib/python3.10/dist-packages/starlette/concurrency.py", line 41, in run_in_threadpool
    return await anyio.to_thread.run_sync(func, *args)
  File "/usr/local/lib/python3.10/dist-packages/anyio/to_thread.py", line 33, in run_sync
    return await get_asynclib().run_sync_in_worker_thread(
  File "/usr/local/lib/python3.10/dist-packages/anyio/_backends/_asyncio.py", line 877, in run_sync_in_worker_thread
    return await future
  File "/usr/local/lib/python3.10/dist-packages/anyio/_backends/_asyncio.py", line 807, in run
    result = context.run(func, *args)
  File "/usr/local/lib/python3.10/dist-packages/gradio/routes.py", line 257, in main
    raise ValueError(
ValueError: Did you install Gradio from source files? Share mode only works when Gradio is installed through the pip package.
ERROR:    Exception in ASGI application
Traceback (most recent call last):
  File "/usr/local/lib/python3.10/dist-packages/gradio/routes.py", line 251, in main
    return templates.TemplateResponse(
  File "/root/cht/gpt_academic/themes/default.py", line 75, in gradio_new_template_fn
    res = gradio_original_template_fn(*args, **kwargs)
  File "/usr/local/lib/python3.10/dist-packages/starlette/templating.py", line 112, in TemplateResponse
    template = self.get_template(name)
  File "/usr/local/lib/python3.10/dist-packages/starlette/templating.py", line 94, in get_template
    return self.env.get_template(name)
  File "/usr/local/lib/python3.10/dist-packages/jinja2/environment.py", line 1010, in get_template
    return self._load_template(name, globals)
  File "/usr/local/lib/python3.10/dist-packages/jinja2/environment.py", line 969, in _load_template
    template = self.loader.load(self, name, self.make_globals(globals))
  File "/usr/local/lib/python3.10/dist-packages/jinja2/loaders.py", line 126, in load
    source, filename, uptodate = self.get_source(environment, name)
  File "/usr/local/lib/python3.10/dist-packages/jinja2/loaders.py", line 218, in get_source
    raise TemplateNotFound(template)
jinja2.exceptions.TemplateNotFound: frontend/share.html

The above exception was the direct cause of the following exception:

Traceback (most recent call last):
  File "/usr/local/lib/python3.10/dist-packages/uvicorn/protocols/http/h11_impl.py", line 408, in run_asgi
    result = await app(  # type: ignore[func-returns-value]
  File "/usr/local/lib/python3.10/dist-packages/uvicorn/middleware/proxy_headers.py", line 84, in __call__
    return await self.app(scope, receive, send)
  File "/usr/local/lib/python3.10/dist-packages/fastapi/applications.py", line 1106, in __call__
    await super().__call__(scope, receive, send)
  File "/usr/local/lib/python3.10/dist-packages/starlette/applications.py", line 122, in __call__
    await self.middleware_stack(scope, receive, send)
  File "/usr/local/lib/python3.10/dist-packages/starlette/middleware/errors.py", line 184, in __call__
    raise exc
  File "/usr/local/lib/python3.10/dist-packages/starlette/middleware/errors.py", line 162, in __call__
    await self.app(scope, receive, _send)
  File "/usr/local/lib/python3.10/dist-packages/starlette/middleware/cors.py", line 83, in __call__
    await self.app(scope, receive, send)
  File "/usr/local/lib/python3.10/dist-packages/starlette/middleware/exceptions.py", line 79, in __call__
    raise exc
  File "/usr/local/lib/python3.10/dist-packages/starlette/middleware/exceptions.py", line 68, in __call__
    await self.app(scope, receive, sender)
  File "/usr/local/lib/python3.10/dist-packages/fastapi/middleware/asyncexitstack.py", line 20, in __call__
    raise e
  File "/usr/local/lib/python3.10/dist-packages/fastapi/middleware/asyncexitstack.py", line 17, in __call__
    await self.app(scope, receive, send)
  File "/usr/local/lib/python3.10/dist-packages/starlette/routing.py", line 718, in __call__
    await route.handle(scope, receive, send)
  File "/usr/local/lib/python3.10/dist-packages/starlette/routing.py", line 276, in handle
    await self.app(scope, receive, send)
  File "/usr/local/lib/python3.10/dist-packages/starlette/routing.py", line 66, in app
    response = await func(request)
  File "/usr/local/lib/python3.10/dist-packages/fastapi/routing.py", line 274, in app
    raw_response = await run_endpoint_function(
  File "/usr/local/lib/python3.10/dist-packages/fastapi/routing.py", line 193, in run_endpoint_function
    return await run_in_threadpool(dependant.call, **values)
  File "/usr/local/lib/python3.10/dist-packages/starlette/concurrency.py", line 41, in run_in_threadpool
    return await anyio.to_thread.run_sync(func, *args)
  File "/usr/local/lib/python3.10/dist-packages/anyio/to_thread.py", line 33, in run_sync
    return await get_asynclib().run_sync_in_worker_thread(
  File "/usr/local/lib/python3.10/dist-packages/anyio/_backends/_asyncio.py", line 877, in run_sync_in_worker_thread
    return await future
  File "/usr/local/lib/python3.10/dist-packages/anyio/_backends/_asyncio.py", line 807, in run
    result = context.run(func, *args)
  File "/usr/local/lib/python3.10/dist-packages/gradio/routes.py", line 257, in main
    raise ValueError(
ValueError: Did you install Gradio from source files? Share mode only works when Gradio is installed through the pip package.
ERROR:    Exception in ASGI application
Traceback (most recent call last):
  File "/usr/local/lib/python3.10/dist-packages/gradio/routes.py", line 251, in main
    return templates.TemplateResponse(
  File "/root/cht/gpt_academic/themes/default.py", line 75, in gradio_new_template_fn
    res = gradio_original_template_fn(*args, **kwargs)
  File "/usr/local/lib/python3.10/dist-packages/starlette/templating.py", line 112, in TemplateResponse
    template = self.get_template(name)
  File "/usr/local/lib/python3.10/dist-packages/starlette/templating.py", line 94, in get_template
    return self.env.get_template(name)
  File "/usr/local/lib/python3.10/dist-packages/jinja2/environment.py", line 1010, in get_template
    return self._load_template(name, globals)
  File "/usr/local/lib/python3.10/dist-packages/jinja2/environment.py", line 969, in _load_template
    template = self.loader.load(self, name, self.make_globals(globals))
  File "/usr/local/lib/python3.10/dist-packages/jinja2/loaders.py", line 126, in load
    source, filename, uptodate = self.get_source(environment, name)
  File "/usr/local/lib/python3.10/dist-packages/jinja2/loaders.py", line 218, in get_source
    raise TemplateNotFound(template)
jinja2.exceptions.TemplateNotFound: frontend/share.html

The above exception was the direct cause of the following exception:

Traceback (most recent call last):
  File "/usr/local/lib/python3.10/dist-packages/uvicorn/protocols/http/h11_impl.py", line 408, in run_asgi
    result = await app(  # type: ignore[func-returns-value]
  File "/usr/local/lib/python3.10/dist-packages/uvicorn/middleware/proxy_headers.py", line 84, in __call__
    return await self.app(scope, receive, send)
  File "/usr/local/lib/python3.10/dist-packages/fastapi/applications.py", line 1106, in __call__
    await super().__call__(scope, receive, send)
  File "/usr/local/lib/python3.10/dist-packages/starlette/applications.py", line 122, in __call__
    await self.middleware_stack(scope, receive, send)
  File "/usr/local/lib/python3.10/dist-packages/starlette/middleware/errors.py", line 184, in __call__
    raise exc
  File "/usr/local/lib/python3.10/dist-packages/starlette/middleware/errors.py", line 162, in __call__
    await self.app(scope, receive, _send)
  File "/usr/local/lib/python3.10/dist-packages/starlette/middleware/cors.py", line 83, in __call__
    await self.app(scope, receive, send)
  File "/usr/local/lib/python3.10/dist-packages/starlette/middleware/exceptions.py", line 79, in __call__
    raise exc
  File "/usr/local/lib/python3.10/dist-packages/starlette/middleware/exceptions.py", line 68, in __call__
    await self.app(scope, receive, sender)
  File "/usr/local/lib/python3.10/dist-packages/fastapi/middleware/asyncexitstack.py", line 20, in __call__
    raise e
  File "/usr/local/lib/python3.10/dist-packages/fastapi/middleware/asyncexitstack.py", line 17, in __call__
    await self.app(scope, receive, send)
  File "/usr/local/lib/python3.10/dist-packages/starlette/routing.py", line 718, in __call__
    await route.handle(scope, receive, send)
  File "/usr/local/lib/python3.10/dist-packages/starlette/routing.py", line 276, in handle
    await self.app(scope, receive, send)
  File "/usr/local/lib/python3.10/dist-packages/starlette/routing.py", line 66, in app
    response = await func(request)
  File "/usr/local/lib/python3.10/dist-packages/fastapi/routing.py", line 274, in app
    raw_response = await run_endpoint_function(
  File "/usr/local/lib/python3.10/dist-packages/fastapi/routing.py", line 193, in run_endpoint_function
    return await run_in_threadpool(dependant.call, **values)
  File "/usr/local/lib/python3.10/dist-packages/starlette/concurrency.py", line 41, in run_in_threadpool
    return await anyio.to_thread.run_sync(func, *args)
  File "/usr/local/lib/python3.10/dist-packages/anyio/to_thread.py", line 33, in run_sync
    return await get_asynclib().run_sync_in_worker_thread(
  File "/usr/local/lib/python3.10/dist-packages/anyio/_backends/_asyncio.py", line 877, in run_sync_in_worker_thread
    return await future
  File "/usr/local/lib/python3.10/dist-packages/anyio/_backends/_asyncio.py", line 807, in run
    result = context.run(func, *args)
  File "/usr/local/lib/python3.10/dist-packages/gradio/routes.py", line 257, in main
    raise ValueError(
ValueError: Did you install Gradio from source files? Share mode only works when Gradio is installed through the pip package.
ERROR:    Exception in ASGI application
Traceback (most recent call last):
  File "/usr/local/lib/python3.10/dist-packages/gradio/routes.py", line 251, in main
    return templates.TemplateResponse(
  File "/root/cht/gpt_academic/themes/default.py", line 75, in gradio_new_template_fn
    res = gradio_original_template_fn(*args, **kwargs)
  File "/usr/local/lib/python3.10/dist-packages/starlette/templating.py", line 112, in TemplateResponse
    template = self.get_template(name)
  File "/usr/local/lib/python3.10/dist-packages/starlette/templating.py", line 94, in get_template
    return self.env.get_template(name)
  File "/usr/local/lib/python3.10/dist-packages/jinja2/environment.py", line 1010, in get_template
    return self._load_template(name, globals)
  File "/usr/local/lib/python3.10/dist-packages/jinja2/environment.py", line 969, in _load_template
    template = self.loader.load(self, name, self.make_globals(globals))
  File "/usr/local/lib/python3.10/dist-packages/jinja2/loaders.py", line 126, in load
    source, filename, uptodate = self.get_source(environment, name)
  File "/usr/local/lib/python3.10/dist-packages/jinja2/loaders.py", line 218, in get_source
    raise TemplateNotFound(template)
jinja2.exceptions.TemplateNotFound: frontend/share.html

The above exception was the direct cause of the following exception:

Traceback (most recent call last):
  File "/usr/local/lib/python3.10/dist-packages/uvicorn/protocols/http/h11_impl.py", line 408, in run_asgi
    result = await app(  # type: ignore[func-returns-value]
  File "/usr/local/lib/python3.10/dist-packages/uvicorn/middleware/proxy_headers.py", line 84, in __call__
    return await self.app(scope, receive, send)
  File "/usr/local/lib/python3.10/dist-packages/fastapi/applications.py", line 1106, in __call__
    await super().__call__(scope, receive, send)
  File "/usr/local/lib/python3.10/dist-packages/starlette/applications.py", line 122, in __call__
    await self.middleware_stack(scope, receive, send)
  File "/usr/local/lib/python3.10/dist-packages/starlette/middleware/errors.py", line 184, in __call__
    raise exc
  File "/usr/local/lib/python3.10/dist-packages/starlette/middleware/errors.py", line 162, in __call__
    await self.app(scope, receive, _send)
  File "/usr/local/lib/python3.10/dist-packages/starlette/middleware/cors.py", line 83, in __call__
    await self.app(scope, receive, send)
  File "/usr/local/lib/python3.10/dist-packages/starlette/middleware/exceptions.py", line 79, in __call__
    raise exc
  File "/usr/local/lib/python3.10/dist-packages/starlette/middleware/exceptions.py", line 68, in __call__
    await self.app(scope, receive, sender)
  File "/usr/local/lib/python3.10/dist-packages/fastapi/middleware/asyncexitstack.py", line 20, in __call__
    raise e
  File "/usr/local/lib/python3.10/dist-packages/fastapi/middleware/asyncexitstack.py", line 17, in __call__
    await self.app(scope, receive, send)
  File "/usr/local/lib/python3.10/dist-packages/starlette/routing.py", line 718, in __call__
    await route.handle(scope, receive, send)
  File "/usr/local/lib/python3.10/dist-packages/starlette/routing.py", line 276, in handle
    await self.app(scope, receive, send)
  File "/usr/local/lib/python3.10/dist-packages/starlette/routing.py", line 66, in app
    response = await func(request)
  File "/usr/local/lib/python3.10/dist-packages/fastapi/routing.py", line 274, in app
    raw_response = await run_endpoint_function(
  File "/usr/local/lib/python3.10/dist-packages/fastapi/routing.py", line 193, in run_endpoint_function
    return await run_in_threadpool(dependant.call, **values)
  File "/usr/local/lib/python3.10/dist-packages/starlette/concurrency.py", line 41, in run_in_threadpool
    return await anyio.to_thread.run_sync(func, *args)
  File "/usr/local/lib/python3.10/dist-packages/anyio/to_thread.py", line 33, in run_sync
    return await get_asynclib().run_sync_in_worker_thread(
  File "/usr/local/lib/python3.10/dist-packages/anyio/_backends/_asyncio.py", line 877, in run_sync_in_worker_thread
    return await future
  File "/usr/local/lib/python3.10/dist-packages/anyio/_backends/_asyncio.py", line 807, in run
    result = context.run(func, *args)
  File "/usr/local/lib/python3.10/dist-packages/gradio/routes.py", line 257, in main
    raise ValueError(
ValueError: Did you install Gradio from source files? Share mode only works when Gradio is installed through the pip package.
ERROR:    Exception in ASGI application
Traceback (most recent call last):
  File "/usr/local/lib/python3.10/dist-packages/gradio/routes.py", line 251, in main
    return templates.TemplateResponse(
  File "/root/cht/gpt_academic/themes/default.py", line 75, in gradio_new_template_fn
    res = gradio_original_template_fn(*args, **kwargs)
  File "/usr/local/lib/python3.10/dist-packages/starlette/templating.py", line 112, in TemplateResponse
    template = self.get_template(name)
  File "/usr/local/lib/python3.10/dist-packages/starlette/templating.py", line 94, in get_template
    return self.env.get_template(name)
  File "/usr/local/lib/python3.10/dist-packages/jinja2/environment.py", line 1010, in get_template
    return self._load_template(name, globals)
  File "/usr/local/lib/python3.10/dist-packages/jinja2/environment.py", line 969, in _load_template
    template = self.loader.load(self, name, self.make_globals(globals))
  File "/usr/local/lib/python3.10/dist-packages/jinja2/loaders.py", line 126, in load
    source, filename, uptodate = self.get_source(environment, name)
  File "/usr/local/lib/python3.10/dist-packages/jinja2/loaders.py", line 218, in get_source
    raise TemplateNotFound(template)
jinja2.exceptions.TemplateNotFound: frontend/share.html

The above exception was the direct cause of the following exception:

Traceback (most recent call last):
  File "/usr/local/lib/python3.10/dist-packages/uvicorn/protocols/http/h11_impl.py", line 408, in run_asgi
    result = await app(  # type: ignore[func-returns-value]
  File "/usr/local/lib/python3.10/dist-packages/uvicorn/middleware/proxy_headers.py", line 84, in __call__
    return await self.app(scope, receive, send)
  File "/usr/local/lib/python3.10/dist-packages/fastapi/applications.py", line 1106, in __call__
    await super().__call__(scope, receive, send)
  File "/usr/local/lib/python3.10/dist-packages/starlette/applications.py", line 122, in __call__
    await self.middleware_stack(scope, receive, send)
  File "/usr/local/lib/python3.10/dist-packages/starlette/middleware/errors.py", line 184, in __call__
    raise exc
  File "/usr/local/lib/python3.10/dist-packages/starlette/middleware/errors.py", line 162, in __call__
    await self.app(scope, receive, _send)
  File "/usr/local/lib/python3.10/dist-packages/starlette/middleware/cors.py", line 83, in __call__
    await self.app(scope, receive, send)
  File "/usr/local/lib/python3.10/dist-packages/starlette/middleware/exceptions.py", line 79, in __call__
    raise exc
  File "/usr/local/lib/python3.10/dist-packages/starlette/middleware/exceptions.py", line 68, in __call__
    await self.app(scope, receive, sender)
  File "/usr/local/lib/python3.10/dist-packages/fastapi/middleware/asyncexitstack.py", line 20, in __call__
    raise e
  File "/usr/local/lib/python3.10/dist-packages/fastapi/middleware/asyncexitstack.py", line 17, in __call__
    await self.app(scope, receive, send)
  File "/usr/local/lib/python3.10/dist-packages/starlette/routing.py", line 718, in __call__
    await route.handle(scope, receive, send)
  File "/usr/local/lib/python3.10/dist-packages/starlette/routing.py", line 276, in handle
    await self.app(scope, receive, send)
  File "/usr/local/lib/python3.10/dist-packages/starlette/routing.py", line 66, in app
    response = await func(request)
  File "/usr/local/lib/python3.10/dist-packages/fastapi/routing.py", line 274, in app
    raw_response = await run_endpoint_function(
  File "/usr/local/lib/python3.10/dist-packages/fastapi/routing.py", line 193, in run_endpoint_function
    return await run_in_threadpool(dependant.call, **values)
  File "/usr/local/lib/python3.10/dist-packages/starlette/concurrency.py", line 41, in run_in_threadpool
    return await anyio.to_thread.run_sync(func, *args)
  File "/usr/local/lib/python3.10/dist-packages/anyio/to_thread.py", line 33, in run_sync
    return await get_asynclib().run_sync_in_worker_thread(
  File "/usr/local/lib/python3.10/dist-packages/anyio/_backends/_asyncio.py", line 877, in run_sync_in_worker_thread
    return await future
  File "/usr/local/lib/python3.10/dist-packages/anyio/_backends/_asyncio.py", line 807, in run
    result = context.run(func, *args)
  File "/usr/local/lib/python3.10/dist-packages/gradio/routes.py", line 257, in main
    raise ValueError(
ValueError: Did you install Gradio from source files? Share mode only works when Gradio is installed through the pip package.
[1;31m [PROXY] 网络代理状态：未配置。无代理状态下很可能无法访问OpenAI家族的模型。建议：检查USE_PROXY选项是否修改。 [0m
所有问询记录将自动保存在本地目录./gpt_log/chat_secrets.log, 请注意自我隐私保护哦！
代理配置 无, 代理所在地：China
[1;34m [API_KEY] 本项目现已支持OpenAI和Azure的api-key。也支持同时填写多个api-key，如API_KEY="openai-key1,openai-key2,azure-key3" [0m
[1;34m [API_KEY] 您既可以在config.py中修改api-key(s)，也可以在问题输入区输入临时的api-key(s)，然后回车键提交后即可生效。 [0m
[1;32m [API_KEY] 您的 API_KEY 是: sk-rwefH6RwYUnw*** API_KEY 导入成功 [0m
如果浏览器没有自动打开，请复制并转到以下URL：
	「暗色主题已启用（支持动态切换主题）」: http://localhost:36925
Traceback (most recent call last):
  File "/usr/local/lib/python3.10/dist-packages/gradio/networking.py", line 121, in start_server
    s.bind((LOCALHOST_NAME, server_port))
OSError: [Errno 98] Address already in use

The above exception was the direct cause of the following exception:

Traceback (most recent call last):
  File "/root/cht/gpt_academic/main.py", line 454, in <module>
    main()
  File "/root/cht/gpt_academic/main.py", line 428, in main
    demo.queue(concurrency_count=CONCURRENT_COUNT).launch(
  File "/usr/local/lib/python3.10/dist-packages/gradio/blocks.py", line 1745, in launch
    server_name, server_port, local_url, app, server = networking.start_server(
  File "/usr/local/lib/python3.10/dist-packages/gradio/networking.py", line 124, in start_server
    raise OSError(
OSError: Port 36925 is in use. If a gradio.Blocks is running on the port, you can close() it or gradio.close_all().
[1;31m [PROXY] 网络代理状态：未配置。无代理状态下很可能无法访问OpenAI家族的模型。建议：检查USE_PROXY选项是否修改。 [0m
所有问询记录将自动保存在本地目录./gpt_log/chat_secrets.log, 请注意自我隐私保护哦！
代理配置 无, 代理所在地：China
[1;34m [API_KEY] 本项目现已支持OpenAI和Azure的api-key。也支持同时填写多个api-key，如API_KEY="openai-key1,openai-key2,azure-key3" [0m
[1;34m [API_KEY] 您既可以在config.py中修改api-key(s)，也可以在问题输入区输入临时的api-key(s)，然后回车键提交后即可生效。 [0m
[1;32m [API_KEY] 您的 API_KEY 是: sk-rwefH6RwYUnw*** API_KEY 导入成功 [0m
如果浏览器没有自动打开，请复制并转到以下URL：
	「暗色主题已启用（支持动态切换主题）」: http://localhost:36925
Traceback (most recent call last):
  File "/usr/local/lib/python3.10/dist-packages/gradio/networking.py", line 121, in start_server
    s.bind((LOCALHOST_NAME, server_port))
OSError: [Errno 98] Address already in use

The above exception was the direct cause of the following exception:

Traceback (most recent call last):
  File "/root/cht/gpt_academic/main.py", line 454, in <module>
    main()
  File "/root/cht/gpt_academic/main.py", line 428, in main
    demo.queue(concurrency_count=CONCURRENT_COUNT).launch(
  File "/usr/local/lib/python3.10/dist-packages/gradio/blocks.py", line 1745, in launch
    server_name, server_port, local_url, app, server = networking.start_server(
  File "/usr/local/lib/python3.10/dist-packages/gradio/networking.py", line 124, in start_server
    raise OSError(
OSError: Port 36925 is in use. If a gradio.Blocks is running on the port, you can close() it or gradio.close_all().
ERROR:    Exception in ASGI application
Traceback (most recent call last):
  File "/usr/local/lib/python3.10/dist-packages/gradio/routes.py", line 251, in main
    return templates.TemplateResponse(
  File "/root/cht/gpt_academic/themes/default.py", line 75, in gradio_new_template_fn
    res = gradio_original_template_fn(*args, **kwargs)
  File "/usr/local/lib/python3.10/dist-packages/starlette/templating.py", line 112, in TemplateResponse
    template = self.get_template(name)
  File "/usr/local/lib/python3.10/dist-packages/starlette/templating.py", line 94, in get_template
    return self.env.get_template(name)
  File "/usr/local/lib/python3.10/dist-packages/jinja2/environment.py", line 1010, in get_template
    return self._load_template(name, globals)
  File "/usr/local/lib/python3.10/dist-packages/jinja2/environment.py", line 969, in _load_template
    template = self.loader.load(self, name, self.make_globals(globals))
  File "/usr/local/lib/python3.10/dist-packages/jinja2/loaders.py", line 126, in load
    source, filename, uptodate = self.get_source(environment, name)
  File "/usr/local/lib/python3.10/dist-packages/jinja2/loaders.py", line 218, in get_source
    raise TemplateNotFound(template)
jinja2.exceptions.TemplateNotFound: frontend/share.html

The above exception was the direct cause of the following exception:

Traceback (most recent call last):
  File "/usr/local/lib/python3.10/dist-packages/uvicorn/protocols/http/h11_impl.py", line 408, in run_asgi
    result = await app(  # type: ignore[func-returns-value]
  File "/usr/local/lib/python3.10/dist-packages/uvicorn/middleware/proxy_headers.py", line 84, in __call__
    return await self.app(scope, receive, send)
  File "/usr/local/lib/python3.10/dist-packages/fastapi/applications.py", line 1106, in __call__
    await super().__call__(scope, receive, send)
  File "/usr/local/lib/python3.10/dist-packages/starlette/applications.py", line 122, in __call__
    await self.middleware_stack(scope, receive, send)
  File "/usr/local/lib/python3.10/dist-packages/starlette/middleware/errors.py", line 184, in __call__
    raise exc
  File "/usr/local/lib/python3.10/dist-packages/starlette/middleware/errors.py", line 162, in __call__
    await self.app(scope, receive, _send)
  File "/usr/local/lib/python3.10/dist-packages/starlette/middleware/cors.py", line 83, in __call__
    await self.app(scope, receive, send)
  File "/usr/local/lib/python3.10/dist-packages/starlette/middleware/exceptions.py", line 79, in __call__
    raise exc
  File "/usr/local/lib/python3.10/dist-packages/starlette/middleware/exceptions.py", line 68, in __call__
    await self.app(scope, receive, sender)
  File "/usr/local/lib/python3.10/dist-packages/fastapi/middleware/asyncexitstack.py", line 20, in __call__
    raise e
  File "/usr/local/lib/python3.10/dist-packages/fastapi/middleware/asyncexitstack.py", line 17, in __call__
    await self.app(scope, receive, send)
  File "/usr/local/lib/python3.10/dist-packages/starlette/routing.py", line 718, in __call__
    await route.handle(scope, receive, send)
  File "/usr/local/lib/python3.10/dist-packages/starlette/routing.py", line 276, in handle
    await self.app(scope, receive, send)
  File "/usr/local/lib/python3.10/dist-packages/starlette/routing.py", line 66, in app
    response = await func(request)
  File "/usr/local/lib/python3.10/dist-packages/fastapi/routing.py", line 274, in app
    raw_response = await run_endpoint_function(
  File "/usr/local/lib/python3.10/dist-packages/fastapi/routing.py", line 193, in run_endpoint_function
    return await run_in_threadpool(dependant.call, **values)
  File "/usr/local/lib/python3.10/dist-packages/starlette/concurrency.py", line 41, in run_in_threadpool
    return await anyio.to_thread.run_sync(func, *args)
  File "/usr/local/lib/python3.10/dist-packages/anyio/to_thread.py", line 33, in run_sync
    return await get_asynclib().run_sync_in_worker_thread(
  File "/usr/local/lib/python3.10/dist-packages/anyio/_backends/_asyncio.py", line 877, in run_sync_in_worker_thread
    return await future
  File "/usr/local/lib/python3.10/dist-packages/anyio/_backends/_asyncio.py", line 807, in run
    result = context.run(func, *args)
  File "/usr/local/lib/python3.10/dist-packages/gradio/routes.py", line 257, in main
    raise ValueError(
ValueError: Did you install Gradio from source files? Share mode only works when Gradio is installed through the pip package.
ERROR:    Exception in ASGI application
Traceback (most recent call last):
  File "/usr/local/lib/python3.10/dist-packages/gradio/routes.py", line 251, in main
    return templates.TemplateResponse(
  File "/root/cht/gpt_academic/themes/default.py", line 75, in gradio_new_template_fn
    res = gradio_original_template_fn(*args, **kwargs)
  File "/usr/local/lib/python3.10/dist-packages/starlette/templating.py", line 112, in TemplateResponse
    template = self.get_template(name)
  File "/usr/local/lib/python3.10/dist-packages/starlette/templating.py", line 94, in get_template
    return self.env.get_template(name)
  File "/usr/local/lib/python3.10/dist-packages/jinja2/environment.py", line 1010, in get_template
    return self._load_template(name, globals)
  File "/usr/local/lib/python3.10/dist-packages/jinja2/environment.py", line 969, in _load_template
    template = self.loader.load(self, name, self.make_globals(globals))
  File "/usr/local/lib/python3.10/dist-packages/jinja2/loaders.py", line 126, in load
    source, filename, uptodate = self.get_source(environment, name)
  File "/usr/local/lib/python3.10/dist-packages/jinja2/loaders.py", line 218, in get_source
    raise TemplateNotFound(template)
jinja2.exceptions.TemplateNotFound: frontend/share.html

The above exception was the direct cause of the following exception:

Traceback (most recent call last):
  File "/usr/local/lib/python3.10/dist-packages/uvicorn/protocols/http/h11_impl.py", line 408, in run_asgi
    result = await app(  # type: ignore[func-returns-value]
  File "/usr/local/lib/python3.10/dist-packages/uvicorn/middleware/proxy_headers.py", line 84, in __call__
    return await self.app(scope, receive, send)
  File "/usr/local/lib/python3.10/dist-packages/fastapi/applications.py", line 1106, in __call__
    await super().__call__(scope, receive, send)
  File "/usr/local/lib/python3.10/dist-packages/starlette/applications.py", line 122, in __call__
    await self.middleware_stack(scope, receive, send)
  File "/usr/local/lib/python3.10/dist-packages/starlette/middleware/errors.py", line 184, in __call__
    raise exc
  File "/usr/local/lib/python3.10/dist-packages/starlette/middleware/errors.py", line 162, in __call__
    await self.app(scope, receive, _send)
  File "/usr/local/lib/python3.10/dist-packages/starlette/middleware/cors.py", line 83, in __call__
    await self.app(scope, receive, send)
  File "/usr/local/lib/python3.10/dist-packages/starlette/middleware/exceptions.py", line 79, in __call__
    raise exc
  File "/usr/local/lib/python3.10/dist-packages/starlette/middleware/exceptions.py", line 68, in __call__
    await self.app(scope, receive, sender)
  File "/usr/local/lib/python3.10/dist-packages/fastapi/middleware/asyncexitstack.py", line 20, in __call__
    raise e
  File "/usr/local/lib/python3.10/dist-packages/fastapi/middleware/asyncexitstack.py", line 17, in __call__
    await self.app(scope, receive, send)
  File "/usr/local/lib/python3.10/dist-packages/starlette/routing.py", line 718, in __call__
    await route.handle(scope, receive, send)
  File "/usr/local/lib/python3.10/dist-packages/starlette/routing.py", line 276, in handle
    await self.app(scope, receive, send)
  File "/usr/local/lib/python3.10/dist-packages/starlette/routing.py", line 66, in app
    response = await func(request)
  File "/usr/local/lib/python3.10/dist-packages/fastapi/routing.py", line 274, in app
    raw_response = await run_endpoint_function(
  File "/usr/local/lib/python3.10/dist-packages/fastapi/routing.py", line 193, in run_endpoint_function
    return await run_in_threadpool(dependant.call, **values)
  File "/usr/local/lib/python3.10/dist-packages/starlette/concurrency.py", line 41, in run_in_threadpool
    return await anyio.to_thread.run_sync(func, *args)
  File "/usr/local/lib/python3.10/dist-packages/anyio/to_thread.py", line 33, in run_sync
    return await get_asynclib().run_sync_in_worker_thread(
  File "/usr/local/lib/python3.10/dist-packages/anyio/_backends/_asyncio.py", line 877, in run_sync_in_worker_thread
    return await future
  File "/usr/local/lib/python3.10/dist-packages/anyio/_backends/_asyncio.py", line 807, in run
    result = context.run(func, *args)
  File "/usr/local/lib/python3.10/dist-packages/gradio/routes.py", line 257, in main
    raise ValueError(
ValueError: Did you install Gradio from source files? Share mode only works when Gradio is installed through the pip package.
ERROR:    Exception in ASGI application
Traceback (most recent call last):
  File "/usr/local/lib/python3.10/dist-packages/gradio/routes.py", line 251, in main
    return templates.TemplateResponse(
  File "/root/cht/gpt_academic/themes/default.py", line 75, in gradio_new_template_fn
    res = gradio_original_template_fn(*args, **kwargs)
  File "/usr/local/lib/python3.10/dist-packages/starlette/templating.py", line 112, in TemplateResponse
    template = self.get_template(name)
  File "/usr/local/lib/python3.10/dist-packages/starlette/templating.py", line 94, in get_template
    return self.env.get_template(name)
  File "/usr/local/lib/python3.10/dist-packages/jinja2/environment.py", line 1010, in get_template
    return self._load_template(name, globals)
  File "/usr/local/lib/python3.10/dist-packages/jinja2/environment.py", line 969, in _load_template
    template = self.loader.load(self, name, self.make_globals(globals))
  File "/usr/local/lib/python3.10/dist-packages/jinja2/loaders.py", line 126, in load
    source, filename, uptodate = self.get_source(environment, name)
  File "/usr/local/lib/python3.10/dist-packages/jinja2/loaders.py", line 218, in get_source
    raise TemplateNotFound(template)
jinja2.exceptions.TemplateNotFound: frontend/share.html

The above exception was the direct cause of the following exception:

Traceback (most recent call last):
  File "/usr/local/lib/python3.10/dist-packages/uvicorn/protocols/http/h11_impl.py", line 408, in run_asgi
    result = await app(  # type: ignore[func-returns-value]
  File "/usr/local/lib/python3.10/dist-packages/uvicorn/middleware/proxy_headers.py", line 84, in __call__
    return await self.app(scope, receive, send)
  File "/usr/local/lib/python3.10/dist-packages/fastapi/applications.py", line 1106, in __call__
    await super().__call__(scope, receive, send)
  File "/usr/local/lib/python3.10/dist-packages/starlette/applications.py", line 122, in __call__
    await self.middleware_stack(scope, receive, send)
  File "/usr/local/lib/python3.10/dist-packages/starlette/middleware/errors.py", line 184, in __call__
    raise exc
  File "/usr/local/lib/python3.10/dist-packages/starlette/middleware/errors.py", line 162, in __call__
    await self.app(scope, receive, _send)
  File "/usr/local/lib/python3.10/dist-packages/starlette/middleware/cors.py", line 83, in __call__
    await self.app(scope, receive, send)
  File "/usr/local/lib/python3.10/dist-packages/starlette/middleware/exceptions.py", line 79, in __call__
    raise exc
  File "/usr/local/lib/python3.10/dist-packages/starlette/middleware/exceptions.py", line 68, in __call__
    await self.app(scope, receive, sender)
  File "/usr/local/lib/python3.10/dist-packages/fastapi/middleware/asyncexitstack.py", line 20, in __call__
    raise e
  File "/usr/local/lib/python3.10/dist-packages/fastapi/middleware/asyncexitstack.py", line 17, in __call__
    await self.app(scope, receive, send)
  File "/usr/local/lib/python3.10/dist-packages/starlette/routing.py", line 718, in __call__
    await route.handle(scope, receive, send)
  File "/usr/local/lib/python3.10/dist-packages/starlette/routing.py", line 276, in handle
    await self.app(scope, receive, send)
  File "/usr/local/lib/python3.10/dist-packages/starlette/routing.py", line 66, in app
    response = await func(request)
  File "/usr/local/lib/python3.10/dist-packages/fastapi/routing.py", line 274, in app
    raw_response = await run_endpoint_function(
  File "/usr/local/lib/python3.10/dist-packages/fastapi/routing.py", line 193, in run_endpoint_function
    return await run_in_threadpool(dependant.call, **values)
  File "/usr/local/lib/python3.10/dist-packages/starlette/concurrency.py", line 41, in run_in_threadpool
    return await anyio.to_thread.run_sync(func, *args)
  File "/usr/local/lib/python3.10/dist-packages/anyio/to_thread.py", line 33, in run_sync
    return await get_asynclib().run_sync_in_worker_thread(
  File "/usr/local/lib/python3.10/dist-packages/anyio/_backends/_asyncio.py", line 877, in run_sync_in_worker_thread
    return await future
  File "/usr/local/lib/python3.10/dist-packages/anyio/_backends/_asyncio.py", line 807, in run
    result = context.run(func, *args)
  File "/usr/local/lib/python3.10/dist-packages/gradio/routes.py", line 257, in main
    raise ValueError(
ValueError: Did you install Gradio from source files? Share mode only works when Gradio is installed through the pip package.
ERROR:    Exception in ASGI application
Traceback (most recent call last):
  File "/usr/local/lib/python3.10/dist-packages/gradio/routes.py", line 251, in main
    return templates.TemplateResponse(
  File "/root/cht/gpt_academic/themes/default.py", line 75, in gradio_new_template_fn
    res = gradio_original_template_fn(*args, **kwargs)
  File "/usr/local/lib/python3.10/dist-packages/starlette/templating.py", line 112, in TemplateResponse
    template = self.get_template(name)
  File "/usr/local/lib/python3.10/dist-packages/starlette/templating.py", line 94, in get_template
    return self.env.get_template(name)
  File "/usr/local/lib/python3.10/dist-packages/jinja2/environment.py", line 1010, in get_template
    return self._load_template(name, globals)
  File "/usr/local/lib/python3.10/dist-packages/jinja2/environment.py", line 969, in _load_template
    template = self.loader.load(self, name, self.make_globals(globals))
  File "/usr/local/lib/python3.10/dist-packages/jinja2/loaders.py", line 126, in load
    source, filename, uptodate = self.get_source(environment, name)
  File "/usr/local/lib/python3.10/dist-packages/jinja2/loaders.py", line 218, in get_source
    raise TemplateNotFound(template)
jinja2.exceptions.TemplateNotFound: frontend/share.html

The above exception was the direct cause of the following exception:

Traceback (most recent call last):
  File "/usr/local/lib/python3.10/dist-packages/uvicorn/protocols/http/h11_impl.py", line 408, in run_asgi
    result = await app(  # type: ignore[func-returns-value]
  File "/usr/local/lib/python3.10/dist-packages/uvicorn/middleware/proxy_headers.py", line 84, in __call__
    return await self.app(scope, receive, send)
  File "/usr/local/lib/python3.10/dist-packages/fastapi/applications.py", line 1106, in __call__
    await super().__call__(scope, receive, send)
  File "/usr/local/lib/python3.10/dist-packages/starlette/applications.py", line 122, in __call__
    await self.middleware_stack(scope, receive, send)
  File "/usr/local/lib/python3.10/dist-packages/starlette/middleware/errors.py", line 184, in __call__
    raise exc
  File "/usr/local/lib/python3.10/dist-packages/starlette/middleware/errors.py", line 162, in __call__
    await self.app(scope, receive, _send)
  File "/usr/local/lib/python3.10/dist-packages/starlette/middleware/cors.py", line 83, in __call__
    await self.app(scope, receive, send)
  File "/usr/local/lib/python3.10/dist-packages/starlette/middleware/exceptions.py", line 79, in __call__
    raise exc
  File "/usr/local/lib/python3.10/dist-packages/starlette/middleware/exceptions.py", line 68, in __call__
    await self.app(scope, receive, sender)
  File "/usr/local/lib/python3.10/dist-packages/fastapi/middleware/asyncexitstack.py", line 20, in __call__
    raise e
  File "/usr/local/lib/python3.10/dist-packages/fastapi/middleware/asyncexitstack.py", line 17, in __call__
    await self.app(scope, receive, send)
  File "/usr/local/lib/python3.10/dist-packages/starlette/routing.py", line 718, in __call__
    await route.handle(scope, receive, send)
  File "/usr/local/lib/python3.10/dist-packages/starlette/routing.py", line 276, in handle
    await self.app(scope, receive, send)
  File "/usr/local/lib/python3.10/dist-packages/starlette/routing.py", line 66, in app
    response = await func(request)
  File "/usr/local/lib/python3.10/dist-packages/fastapi/routing.py", line 274, in app
    raw_response = await run_endpoint_function(
  File "/usr/local/lib/python3.10/dist-packages/fastapi/routing.py", line 193, in run_endpoint_function
    return await run_in_threadpool(dependant.call, **values)
  File "/usr/local/lib/python3.10/dist-packages/starlette/concurrency.py", line 41, in run_in_threadpool
    return await anyio.to_thread.run_sync(func, *args)
  File "/usr/local/lib/python3.10/dist-packages/anyio/to_thread.py", line 33, in run_sync
    return await get_asynclib().run_sync_in_worker_thread(
  File "/usr/local/lib/python3.10/dist-packages/anyio/_backends/_asyncio.py", line 877, in run_sync_in_worker_thread
    return await future
  File "/usr/local/lib/python3.10/dist-packages/anyio/_backends/_asyncio.py", line 807, in run
    result = context.run(func, *args)
  File "/usr/local/lib/python3.10/dist-packages/gradio/routes.py", line 257, in main
    raise ValueError(
ValueError: Did you install Gradio from source files? Share mode only works when Gradio is installed through the pip package.
ERROR:    Exception in ASGI application
Traceback (most recent call last):
  File "/usr/local/lib/python3.10/dist-packages/gradio/routes.py", line 251, in main
    return templates.TemplateResponse(
  File "/root/cht/gpt_academic/themes/default.py", line 75, in gradio_new_template_fn
    res = gradio_original_template_fn(*args, **kwargs)
  File "/usr/local/lib/python3.10/dist-packages/starlette/templating.py", line 112, in TemplateResponse
    template = self.get_template(name)
  File "/usr/local/lib/python3.10/dist-packages/starlette/templating.py", line 94, in get_template
    return self.env.get_template(name)
  File "/usr/local/lib/python3.10/dist-packages/jinja2/environment.py", line 1010, in get_template
    return self._load_template(name, globals)
  File "/usr/local/lib/python3.10/dist-packages/jinja2/environment.py", line 969, in _load_template
    template = self.loader.load(self, name, self.make_globals(globals))
  File "/usr/local/lib/python3.10/dist-packages/jinja2/loaders.py", line 126, in load
    source, filename, uptodate = self.get_source(environment, name)
  File "/usr/local/lib/python3.10/dist-packages/jinja2/loaders.py", line 218, in get_source
    raise TemplateNotFound(template)
jinja2.exceptions.TemplateNotFound: frontend/share.html

The above exception was the direct cause of the following exception:

Traceback (most recent call last):
  File "/usr/local/lib/python3.10/dist-packages/uvicorn/protocols/http/h11_impl.py", line 408, in run_asgi
    result = await app(  # type: ignore[func-returns-value]
  File "/usr/local/lib/python3.10/dist-packages/uvicorn/middleware/proxy_headers.py", line 84, in __call__
    return await self.app(scope, receive, send)
  File "/usr/local/lib/python3.10/dist-packages/fastapi/applications.py", line 1106, in __call__
    await super().__call__(scope, receive, send)
  File "/usr/local/lib/python3.10/dist-packages/starlette/applications.py", line 122, in __call__
    await self.middleware_stack(scope, receive, send)
  File "/usr/local/lib/python3.10/dist-packages/starlette/middleware/errors.py", line 184, in __call__
    raise exc
  File "/usr/local/lib/python3.10/dist-packages/starlette/middleware/errors.py", line 162, in __call__
    await self.app(scope, receive, _send)
  File "/usr/local/lib/python3.10/dist-packages/starlette/middleware/cors.py", line 83, in __call__
    await self.app(scope, receive, send)
  File "/usr/local/lib/python3.10/dist-packages/starlette/middleware/exceptions.py", line 79, in __call__
    raise exc
  File "/usr/local/lib/python3.10/dist-packages/starlette/middleware/exceptions.py", line 68, in __call__
    await self.app(scope, receive, sender)
  File "/usr/local/lib/python3.10/dist-packages/fastapi/middleware/asyncexitstack.py", line 20, in __call__
    raise e
  File "/usr/local/lib/python3.10/dist-packages/fastapi/middleware/asyncexitstack.py", line 17, in __call__
    await self.app(scope, receive, send)
  File "/usr/local/lib/python3.10/dist-packages/starlette/routing.py", line 718, in __call__
    await route.handle(scope, receive, send)
  File "/usr/local/lib/python3.10/dist-packages/starlette/routing.py", line 276, in handle
    await self.app(scope, receive, send)
  File "/usr/local/lib/python3.10/dist-packages/starlette/routing.py", line 66, in app
    response = await func(request)
  File "/usr/local/lib/python3.10/dist-packages/fastapi/routing.py", line 274, in app
    raw_response = await run_endpoint_function(
  File "/usr/local/lib/python3.10/dist-packages/fastapi/routing.py", line 193, in run_endpoint_function
    return await run_in_threadpool(dependant.call, **values)
  File "/usr/local/lib/python3.10/dist-packages/starlette/concurrency.py", line 41, in run_in_threadpool
    return await anyio.to_thread.run_sync(func, *args)
  File "/usr/local/lib/python3.10/dist-packages/anyio/to_thread.py", line 33, in run_sync
    return await get_asynclib().run_sync_in_worker_thread(
  File "/usr/local/lib/python3.10/dist-packages/anyio/_backends/_asyncio.py", line 877, in run_sync_in_worker_thread
    return await future
  File "/usr/local/lib/python3.10/dist-packages/anyio/_backends/_asyncio.py", line 807, in run
    result = context.run(func, *args)
  File "/usr/local/lib/python3.10/dist-packages/gradio/routes.py", line 257, in main
    raise ValueError(
ValueError: Did you install Gradio from source files? Share mode only works when Gradio is installed through the pip package.
[1;31m [PROXY] 网络代理状态：未配置。无代理状态下很可能无法访问OpenAI家族的模型。建议：检查USE_PROXY选项是否修改。 [0m
所有问询记录将自动保存在本地目录./gpt_log/chat_secrets.log, 请注意自我隐私保护哦！
代理配置 无, 代理所在地：China
[1;34m [API_KEY] 本项目现已支持OpenAI和Azure的api-key。也支持同时填写多个api-key，如API_KEY="openai-key1,openai-key2,azure-key3" [0m
[1;34m [API_KEY] 您既可以在config.py中修改api-key(s)，也可以在问题输入区输入临时的api-key(s)，然后回车键提交后即可生效。 [0m
[1;32m [API_KEY] 您的 API_KEY 是: sk-rwefH6RwYUnw*** API_KEY 导入成功 [0m
如果浏览器没有自动打开，请复制并转到以下URL：
	「暗色主题已启用（支持动态切换主题）」: http://localhost:1478
Running on local URL:  http://0.0.0.0:1478
正在执行一些模块的预热 ...
正在加载tokenizer，如果是第一次运行，可能需要一点时间下载参数
加载tokenizer完毕
正在加载tokenizer，如果是第一次运行，可能需要一点时间下载参数
加载tokenizer完毕
Traceback (most recent call last):
  File "/root/cht/gpt_academic/main.py", line 454, in <module>
    main()
  File "/root/cht/gpt_academic/main.py", line 428, in main
    demo.queue(concurrency_count=CONCURRENT_COUNT).launch(
  File "/usr/local/lib/python3.10/dist-packages/gradio/blocks.py", line 1834, in launch
    self.share_url = networking.setup_tunnel(
  File "/usr/local/lib/python3.10/dist-packages/gradio/networking.py", line 169, in setup_tunnel
    response = requests.get(GRADIO_API_SERVER)
  File "/usr/local/lib/python3.10/dist-packages/requests/api.py", line 73, in get
    return request("get", url, params=params, **kwargs)
  File "/usr/local/lib/python3.10/dist-packages/requests/api.py", line 59, in request
    return session.request(method=method, url=url, **kwargs)
  File "/usr/local/lib/python3.10/dist-packages/requests/sessions.py", line 587, in request
    resp = self.send(prep, **send_kwargs)
  File "/usr/local/lib/python3.10/dist-packages/requests/sessions.py", line 701, in send
    r = adapter.send(request, **kwargs)
  File "/usr/local/lib/python3.10/dist-packages/requests/adapters.py", line 486, in send
    resp = conn.urlopen(
  File "/usr/local/lib/python3.10/dist-packages/urllib3/connectionpool.py", line 790, in urlopen
    response = self._make_request(
  File "/usr/local/lib/python3.10/dist-packages/urllib3/connectionpool.py", line 536, in _make_request
    response = conn.getresponse()
  File "/usr/local/lib/python3.10/dist-packages/urllib3/connection.py", line 454, in getresponse
    httplib_response = super().getresponse()
  File "/usr/lib/python3.10/http/client.py", line 1375, in getresponse
    response.begin()
  File "/usr/lib/python3.10/http/client.py", line 318, in begin
    version, status, reason = self._read_status()
  File "/usr/lib/python3.10/http/client.py", line 279, in _read_status
    line = str(self.fp.readline(_MAXLINE + 1), "iso-8859-1")
  File "/usr/lib/python3.10/socket.py", line 705, in readinto
    return self._sock.recv_into(b)
  File "/usr/lib/python3.10/ssl.py", line 1303, in recv_into
    return self.read(nbytes, buffer)
  File "/usr/lib/python3.10/ssl.py", line 1159, in read
    return self._sslobj.read(len, buffer)
KeyboardInterrupt
WARNING:  Invalid HTTP request received.
WARNING:  Invalid HTTP request received.
